public class ExceptionTest {
    public static void main(String[] args) {
        ExceptionTest et = new ExceptionTest();
        try {
            et.test01();
        } catch (Exception e) {
            System.err.println("test01 error:" + e.getMessage());
        }
    }

    private boolean test01() {
        boolean ret = true;
        try {
            ret = test02();
        } catch (Exception e) {
            System.err.println("test01 error:" + e.getMessage());
            ret = false;
        } finally {
            System.err.println("test01,finally, return -> " + ret);
            return ret;
        }
    }

    private boolean test02() {
        boolean ret = true;
        try {
            //问题1：test03发生异常了，虽然try-catch了，但调用的地方没有接收
            test03();
            System.out.println("因为test03报错，我不应该执行。");
            return ret;
        } catch (Exception e) {
            System.err.println("test02 error:" + e.getMessage());
            ret = false;
            throw e;
        } finally {
            System.out.println("test02 finally, return -> " + ret);
            return ret;
        }
    }

    private boolean test03() throws Exception {
        boolean ret = true;
        try {
            System.out.println("我是松山院");
            System.out.println("即将发生异常");
            int a = 1 / 0;
            System.out.println("发生异常后，还能执行我吗？");
            return true;
        } catch (Exception e) {
            System.err.println("test03 error:" + e.getMessage());
            ret = false;
            throw e;
        } finally {
            System.err.println("test03 finally, return -> " + ret);
            return ret;
        }
    }
}
